<?xml version="1.0" ?> 
<robot name="turtlebot" xmlns:xacro="http://www.ros.org/wiki/xacro">

    <link name="base_footprint"/>

    <link name="base_link">
        <inertial>
            <origin xyz="0.0 0.0 0.0" rpy="0.0 0.0 0.0"/>
            <mass value="5.0"/>
            <inertia ixx="0.001" ixy="0.0" ixz="0.0" iyy="0.001" iyz="0.0" izz="0.001"/>
        </inertial>
        <visual>
            <origin xyz="0.0 0.0 0.0" rpy="0.0 0.0 0.0"/>
            <geometry>
                <mesh filename="package://turtlebot_description/meshes/turtlebot.stl" scale="0.001 0.001 0.001"/>
            </geometry>
            <material name="cyan">
                <color rgba="0.0 1.0 1.0 1.0"/>
            </material>
        </visual>
        <collision>
            <origin xyz="0.0 0.0 0.0" rpy="0.0 0.0 0.0"/>
            <geometry>
                <mesh filename="package://turtlebot_description/meshes/turtlebot.stl" scale="0.001 0.001 0.001"/>
            </geometry>
            <material name="cyan">
                <color rgba="0.0 1.0 1.0 1.0"/>
            </material>
        </collision>
    </link>

    <joint name="base_joint" type="fixed">
        <origin xyz="0.0 0.0 0.020136" rpy="0.0 0.0 0.0"/>
        <parent link="base_footprint"/>
        <child link="base_link"/>
    </joint>

    <link name="right_wheel_link">
        <inertial>
            <origin xyz="0.0 0.0 0.0" rpy="0.0 0.0 0.0"/>
            <mass value="0.5"/>
            <inertia ixx="0.001" ixy="0.0" ixz="0.0" iyy="0.001" iyz="0.0" izz="0.001"/>
        </inertial>
        <visual>
            <origin xyz="0.0 0.0 0.0" rpy="0.0 0.0 0.0"/>
            <geometry>
                <mesh filename="package://turtlebot_description/meshes/Wheel.stl" scale="0.001 0.001 0.001"/>
            </geometry>
            <material name="black">
                <color rgba="0.0 0.0 0.0 1.0"/>
            </material>
        </visual>
        <collision>
            <origin xyz="0.0 0.0 0.0" rpy="0.0 0.0 0.0"/>
            <geometry>
                <mesh filename="package://turtlebot_description/meshes/Wheel.stl" scale="0.001 0.001 0.001"/>
            </geometry>
            <material name="black">
                <color rgba="0.0 0.0 0.0 1.0"/>
            </material>
        </collision>
    </link>

    <joint name="right_wheel_joint" type="continuous">
        <origin xyz="-0.0212 -0.1112928 0.039" rpy="0.0 0.0 0.0"/>
        <parent link="base_link"/>
        <child link="right_wheel_link"/>
        <axis xyz="0.0 1.0 0.0"/>
    </joint>

    <link name="left_wheel_link">
        <inertial>
            <origin xyz="0.0 0.0 0.0" rpy="0.0 0.0 0.0"/>
            <mass value="0.5"/>
            <inertia ixx="0.001" ixy="0.0" ixz="0.0" iyy="0.001" iyz="0.0" izz="0.001"/>
        </inertial>
        <visual>
            <origin xyz="0.0 0.0 0.0" rpy="0.0 0.0 0.0"/>
            <geometry>
                <mesh filename="package://turtlebot_description/meshes/Wheel.stl" scale="0.001 0.001 0.001"/>
            </geometry>
            <material name="black">
                <color rgba="0.0 0.0 0.0 1.0"/>
            </material>
        </visual>
        <collision>
            <origin xyz="0.0 0.0 0.0" rpy="0.0 0.0 0.0"/>
            <geometry>
                <mesh filename="package://turtlebot_description/meshes/Wheel.stl" scale="0.001 0.001 0.001"/>
            </geometry>
            <material name="black">
                <color rgba="0.0 0.0 0.0 1.0"/>
            </material>
        </collision>
    </link>

    <joint name="left_wheel_joint" type="continuous">
        <origin xyz="-0.021442 0.113308 0.039" rpy="0.0 0.0 0.0"/>
        <parent link="base_link"/>
        <child link="left_wheel_link"/>
        <axis xyz="0.0 1.0 0.0"/>
    </joint>

    <link name="caster_wheel_link">
        <inertial>
            <origin xyz="-0.085 0.065 -0.021" rpy="0.0 0.0 0.0"/>
            <mass value="0.1"/>
            <inertia ixx="0.001" ixy="0.0" ixz="0.0" iyy="0.001" iyz="0.0" izz="0.001"/>
        </inertial>
        <visual>
            <origin xyz="0.0 0.0 0.0" rpy="0.0 0.0 0.0"/>
            <geometry>
                <mesh filename="package://turtlebot_description/meshes/caster_wheel.stl" scale="0.001 0.001 0.001"/>
            </geometry>
            <material name="silver">
                <color rgba="0.5 0.5 0.5 1.0"/>
            </material>
        </visual>
        <collision>
            <origin xyz="0.0 0.0 0.0" rpy="0.0 0.0 0.0"/>
            <geometry>
                <mesh filename="package://turtlebot_description/meshes/caster_wheel.stl" scale="0.001 0.001 0.001"/>
            </geometry>
            <material name="silver">
                <color rgba="0.5 0.5 0.5 1.0"/>
            </material>
        </collision>
    </link>

    <joint name="caster_wheel_joint" type="fixed">
        <origin xyz="0.055184 0.000981 0.018497" rpy="3.14159 0.0 0.0"/>
        <parent link="base_link"/>
        <child link="caster_wheel_link"/>
    </joint>

</robot>